<?xml version="1.0"?>

<robot name="hiwonder" xmlns:xacro="http://ros.org/wiki/xacro">

  <gazebo>

    <plugin
        filename="gz-sim-ackermann-steering-system"
        name="gz::sim::systems::AckermannSteering">
        <left_joint>front_left_wheel_joint</left_joint>
        <left_joint>rear_left_wheel_joint</left_joint>
        <right_joint>front_right_wheel_joint</right_joint>
        <right_joint>rear_right_wheel_joint</right_joint>
        <left_steering_joint>front_left_wheel_joint_steering</left_steering_joint>
        <right_steering_joint>front_right_wheel_joint_steering</right_steering_joint>
        <wheel_separation>0.7</wheel_separation>
        <wheel_base>0.5</wheel_base>
        <wheel_radius>0.1</wheel_radius>
        <odom_publish_frequency>50</odom_publish_frequency>
        <topic>cmd_vel</topic>
    </plugin>

    <plugin
        filename="gz-sim-joint-state-publisher-system"
        name="gz::sim::systems::JointStatePublisher">
        <topic>joint_states</topic>
    </plugin>

    <plugin
      filename="gz-sim-sensors-system"
      name="gz::sim::systems::Sensors">
      <render_engine>ogre2</render_engine>
    </plugin>

  </gazebo>


  <link name="base_link">
    <visual>
      <geometry>
        <box size="0.9 0.7 0.1"/>
      </geometry>
      <material name="blue">
        <color rgba="0.0 0.0 1.0 1.0"/>
      </material>
    </visual>
    
    <collision>
      <geometry>
        <box size="0.9 0.7 0.1"/>
      </geometry>
    </collision>
    
    <inertial>
      <mass value="5.0"/>
      <origin xyz="0 0 0" rpy="0 0 0"/>
      <inertia ixx="0.5" ixy="0.0" ixz="0.0" 
               iyy="0.5" iyz="0.0" 
               izz="0.5"/>
    </inertial>
  </link>

  <link name="lidar_link">
    <visual>
      <geometry>
        <cylinder radius="0.05" length="0.04"/>
      </geometry>
      <material name="maroon">
        <color rgba="0.5 0.0 0.0 1.0"/>
      </material>
    </visual>
    
    <collision>
      <geometry>
        <cylinder radius="0.05" length="0.04"/>
      </geometry>
    </collision>
    
    <inertial>
      <mass value="0.1"/>
      <origin xyz="0 0 0" rpy="0 0 0"/>
      <inertia ixx="0.001" ixy="0.0" ixz="0.0" 
              iyy="0.001" iyz="0.0" 
              izz="0.001"/>
    </inertial>
  </link>

  <joint name="lidar_joint" type="fixed">
    <origin xyz="0.3 0 0.15" rpy="0 0 0"/>
    <parent link="base_link"/>
    <child link="lidar_link"/>
  </joint>

  <gazebo reference="lidar_link">
   
    <sensor name='gpu_lidar' type='gpu_lidar'>
      <pose>0 0 0 0 0 0</pose>
      <topic>lidar</topic>
      <update_rate>10</update_rate>
      <frame_id>lidar_link</frame_id>
      <ray>
          <scan>
              <horizontal>
                  <samples>640</samples>
                  <resolution>1</resolution>
                  <min_angle>-1.396263</min_angle>
                  <max_angle>1.396263</max_angle>
              </horizontal>
              <vertical>
                  <samples>1</samples>
                  <resolution>0.01</resolution>
                  <min_angle>0</min_angle>
                  <max_angle>0</max_angle>
              </vertical>
          </scan>
          <range>
              <min>0.08</min>
              <max>10.0</max>
              <resolution>0.01</resolution>
          </range>
      </ray>
      <always_on>1</always_on>
      <visualize>true</visualize>
    </sensor>
    
  </gazebo>


  <link name="camera_link">
    <visual>
      <geometry>
        <box size="0.06 0.08 0.06"/>
      </geometry>
      <material name="white">
        <color rgba="1.0 1.0 1.0 1.0"/>
      </material>
    </visual>
    
    <collision>
      <geometry>
        <box size="0.06 0.08 0.06"/>
      </geometry>
    </collision>
    
    <inertial>
      <mass value="0.05"/>
      <origin xyz="0 0 0" rpy="0 0 0"/>
      <inertia ixx="0.001" ixy="0.0" ixz="0.0" 
              iyy="0.001" iyz="0.0" 
              izz="0.001"/>
    </inertial>
  </link>

  <joint name="camera_joint" type="fixed">
    <origin xyz="0.55 0 0.065" rpy="0 0 0"/>
    <parent link="base_link"/>
    <child link="camera_link"/>
  </joint>

  <gazebo reference="camera_link">
    <sensor name="camera" type="camera">
      <pose>0 0 0 0 0 0</pose>
      <topic>camera</topic>
      <update_rate>30</update_rate>
      <frame_id>camera_link</frame_id>
      <camera>
        <horizontal_fov>1.047198</horizontal_fov>
        <visibility_mask>268435454</visibility_mask>
        <image>
          <width>640</width>
          <height>480</height>
          <format>R8G8B8</format>
        </image>
        <clip>
          <near>0.5</near>
          <far>300</far>
        </clip>
      </camera>
      <always_on>1</always_on>
      <visualize>true</visualize>
    </sensor>
  </gazebo>


   <!-- Wheel Macro -->
  <xacro:macro name="rear_wheel" params="name x y">
    <link name="${name}">
      <visual>
        <geometry>
          <cylinder length="0.08" radius="0.1"/>
        </geometry>
        <material name="black">
          <color rgba="0.1 0.1 0.1 1.0"/>
        </material>
      </visual>
      <collision>
        <geometry>
          <cylinder length="0.08" radius="0.1"/>
        </geometry>
      </collision>
      <inertial>
        <mass value="0.2"/>
        <origin xyz="0 0 0" rpy="0 0 0"/>
        <inertia ixx="0.01" ixy="0" ixz="0"
                 iyy="0.01" iyz="0"
                 izz="0.01"/>
      </inertial>
    </link>

    <joint name="${name}_joint" type="continuous">
      <origin xyz="${x} ${y} -0.2" rpy="1.5708 0 0"/>
      <parent link="base_link"/>
      <child link="${name}"/>
      <axis xyz="0 0 -1"/>
    </joint>
  </xacro:macro>

  <xacro:macro name="front_wheel" params="name x y">
    <link name="${name}">
      <visual>
        <geometry>
          <cylinder length="0.08" radius="0.1"/>
        </geometry>
        <material name="black">
          <color rgba="0.1 0.1 0.1 1.0"/>
        </material>
      </visual>
      <collision>
        <geometry>
          <cylinder length="0.08" radius="0.1"/>
        </geometry>
      </collision>
      <inertial>
        <mass value="0.2"/>
        <origin xyz="0 0 0" rpy="0 0 0"/>
        <inertia ixx="0.01" ixy="0" ixz="0"
                 iyy="0.01" iyz="0"
                 izz="0.01"/>
      </inertial>
    </link>

    <link name="${name}_steering">
      <inertial>
      <mass value="0.001"/>
      <origin xyz="0 0 0" rpy="0 0 0"/>
      <inertia ixx="0.00001" ixy="0.0" ixz="0.0" 
              iyy="0.00001" iyz="0.0" 
              izz="0.00001"/>
    </inertial>
    </link>

    <joint name="${name}_joint_steering" type="revolute">
      <origin xyz="${x} ${y} -0.2" rpy="0 0 0"/>
      <parent link="base_link"/>
      <child link="${name}_steering"/>
      <axis xyz="0 0 1"/>
      <limit lower="-0.5" upper="0.5" effort="10" velocity="1.0"/>
    </joint>
    <joint name="${name}_joint" type="continuous">
      <origin xyz="0 0 0" rpy="1.5708 0 0"/>
      <parent link="${name}_steering"/>
      <child link="${name}"/>
      <axis xyz="0 0 -1"/>
    </joint>
    
  </xacro:macro>

  <xacro:front_wheel name="front_left_wheel"  x="0.35" y="0.25"/>
  <xacro:front_wheel name="front_right_wheel" x="0.35" y="-0.25"/>
  <xacro:rear_wheel name="rear_left_wheel"   x="-0.35" y="0.25"/>
  <xacro:rear_wheel name="rear_right_wheel"  x="-0.35" y="-0.25"/>

<gazebo reference="lidar_link">
  <visual>
    <visibility_flags>1</visibility_flags>
  </visual>
</gazebo>

<gazebo reference="camera_link">
  <visual>
    <visibility_flags>1</visibility_flags>
  </visual>
</gazebo>

<gazebo reference="front_left_wheel">
  <visual>
    <visibility_flags>1</visibility_flags>
  </visual>
</gazebo>

<gazebo reference="front_right_wheel">
  <visual>
    <visibility_flags>1</visibility_flags>
  </visual>
</gazebo>

<gazebo reference="rear_left_wheel">
  <visual>
    <visibility_flags>1</visibility_flags>
  </visual>
</gazebo>

<gazebo reference="rear_right_wheel">
  <visual>
    <visibility_flags>1</visibility_flags>
  </visual>
</gazebo>

</robot>