<?xml version="1.0"?>

<robot name="hiwonder" xmlns:xacro="http://ros.org/wiki/xacro">

  <gazebo>

    <plugin
        filename="gz-sim-diff-drive-system"
        name="gz::sim::systems::DiffDrive">
        <left_joint>front_left_wheel_joint</left_joint>
        <right_joint>front_right_wheel_joint</right_joint>
        <wheel_separation>0.7</wheel_separation>
        <wheel_radius>0.1</wheel_radius>
        <odom_publish_frequency>1</odom_publish_frequency>
        <topic>cmd_vel</topic>
    </plugin>

    <!-- <plugin
        filename="gz-sim-ackermann-steering-system"
        name="gz::sim::systems::AckermannSteering">
        <left_joint>front_left_wheel_joint</left_joint>
        <left_joint>rear_left_wheel_joint</left_joint>
        <right_joint>front_right_wheel_joint</right_joint>
        <right_joint>rear_right_wheel_joint</right_joint>
        <left_steering_joint>front_left_wheel_joint</left_steering_joint>
        <right_steering_joint>front_right_wheel_joint</right_steering_joint>
        <wheel_separation>0.7</wheel_separation>
        <wheel_base>0.5</wheel_base>
        <wheel_radius>0.1</wheel_radius>
        <odom_publish_frequency>1</odom_publish_frequency>
        <topic>cmd_vel</topic>
    </plugin> -->
  </gazebo>

  <link name="base_link">
    <visual>
      <geometry>
        <box size="0.9 0.7 0.1"/>
      </geometry>
      <material name="blue">
        <color rgba="0.0 0.0 1.0 1.0"/>
      </material>
    </visual>
    
    <collision>
      <geometry>
        <box size="0.9 0.7 0.1"/>
      </geometry>
    </collision>
    
    <inertial>
      <mass value="5.0"/>
      <origin xyz="0 0 0" rpy="0 0 0"/>
      <inertia ixx="0.5" ixy="0.0" ixz="0.0" 
               iyy="0.5" iyz="0.0" 
               izz="0.5"/>
    </inertial>
  </link>

   <!-- Wheel Macro -->
  <xacro:macro name="wheel" params="name x y">
    <link name="${name}">
      <visual>
        <geometry>
          <cylinder length="0.08" radius="0.1"/>
        </geometry>
        <material name="black">
          <color rgba="0.1 0.1 0.1 1.0"/>
        </material>
      </visual>
      <collision>
        <geometry>
          <cylinder length="0.08" radius="0.1"/>
        </geometry>
      </collision>
      <inertial>
        <mass value="0.2"/>
        <origin xyz="0 0 0" rpy="0 0 0"/>
        <inertia ixx="0.01" ixy="0" ixz="0"
                 iyy="0.01" iyz="0"
                 izz="0.01"/>
      </inertial>
    </link>

    <joint name="${name}_joint" type="continuous">
      <origin xyz="${x} ${y} -0.2" rpy="1.5708 0 0"/>
      <parent link="base_link"/>
      <child link="${name}"/>
      <axis xyz="0 0 1"/>
    </joint>
  </xacro:macro>

  <xacro:wheel name="front_left_wheel"  x="0.35" y="0.25"/>
  <xacro:wheel name="front_right_wheel" x="0.35" y="-0.25"/>
  <xacro:wheel name="rear_left_wheel"   x="-0.35" y="0.25"/>
  <xacro:wheel name="rear_right_wheel"  x="-0.35" y="-0.25"/>
  
</robot>